"2021-12-05 00:52:13,886 - [INFO] -  logs.logger - (bot.py).start_polling(57) - Start polling"
"2021-12-05 00:55:21,155 - [INFO] -  logs.logger - (bot.py).start_polling(65) - Stop polling"
"2021-12-05 00:55:21,173 - [ERROR] -  asyncio - (base_events.py).default_exception_handler(1738) - Task exception was never retrieved
future: <Task finished name='Task-1' coro=<Bot.run() done, defined at /home/nick/PycharmProjects/vkbot/bot/bot.py:45> exception=KeyboardInterrupt()>"
Traceback (most recent call last):
  File "/home/nick/PycharmProjects/vkbot/bot/bot.py", line 62, in start_polling
    logger.critical(f"CRITICAL {e}")
  File "/usr/lib/python3.9/asyncio/base_events.py", line 596, in run_forever
    self._run_once()
  File "/usr/lib/python3.9/asyncio/base_events.py", line 1890, in _run_once
    handle._run()
  File "/usr/lib/python3.9/asyncio/events.py", line 80, in _run
    self._context.run(self._callback, *self._args)
  File "/home/nick/PycharmProjects/vkbot/bot/bot.py", line 46, in run
  File "/home/nick/.local/lib/python3.9/site-packages/vk_api/longpoll.py", line 621, in listen
    for event in self.check():
  File "/home/nick/.local/lib/python3.9/site-packages/vk_api/longpoll.py", line 557, in check
    response = self.session.get(
  File "/usr/lib/python3/dist-packages/requests/sessions.py", line 543, in get
    return self.request('GET', url, **kwargs)
  File "/usr/lib/python3/dist-packages/requests/sessions.py", line 530, in request
    resp = self.send(prep, **send_kwargs)
  File "/usr/lib/python3/dist-packages/requests/sessions.py", line 643, in send
    r = adapter.send(request, **kwargs)
  File "/usr/lib/python3/dist-packages/requests/adapters.py", line 439, in send
    resp = conn.urlopen(
  File "/usr/lib/python3/dist-packages/urllib3/connectionpool.py", line 670, in urlopen
    httplib_response = self._make_request(
  File "/usr/lib/python3/dist-packages/urllib3/connectionpool.py", line 426, in _make_request
    six.raise_from(e, None)
  File "<string>", line 3, in raise_from
  File "/usr/lib/python3/dist-packages/urllib3/connectionpool.py", line 421, in _make_request
    httplib_response = conn.getresponse()
  File "/usr/lib/python3.9/http/client.py", line 1347, in getresponse
    response.begin()
  File "/usr/lib/python3.9/http/client.py", line 307, in begin
    version, status, reason = self._read_status()
  File "/usr/lib/python3.9/http/client.py", line 268, in _read_status
    line = str(self.fp.readline(_MAXLINE + 1), "iso-8859-1")
  File "/usr/lib/python3.9/socket.py", line 704, in readinto
    return self._sock.recv_into(b)
  File "/usr/lib/python3.9/ssl.py", line 1241, in recv_into
    return self.read(nbytes, buffer)
  File "/usr/lib/python3.9/ssl.py", line 1099, in read
    return self._sslobj.read(len, buffer)
KeyboardInterrupt
"2021-12-05 00:55:22,195 - [INFO] -  logs.logger - (bot.py).start_polling(53) - Start polling"
"2021-12-05 00:56:03,803 - [INFO] -  logs.logger - (bot.py).start_polling(59) - Stop polling"
"2021-12-05 00:56:03,818 - [ERROR] -  asyncio - (base_events.py).default_exception_handler(1738) - Task exception was never retrieved
future: <Task finished name='Task-1' coro=<Bot.run() done, defined at /home/nick/PycharmProjects/vkbot/bot/bot.py:41> exception=KeyboardInterrupt()>"
Traceback (most recent call last):
  File "/home/nick/PycharmProjects/vkbot/bot/bot.py", line 57, in start_polling
    main_loop.run_forever()
  File "/usr/lib/python3.9/asyncio/base_events.py", line 596, in run_forever
    self._run_once()
  File "/usr/lib/python3.9/asyncio/base_events.py", line 1890, in _run_once
    handle._run()
  File "/usr/lib/python3.9/asyncio/events.py", line 80, in _run
    self._context.run(self._callback, *self._args)
  File "/home/nick/PycharmProjects/vkbot/bot/bot.py", line 42, in run
    for event in self._longpoll.listen():
  File "/home/nick/.local/lib/python3.9/site-packages/vk_api/longpoll.py", line 621, in listen
    for event in self.check():
  File "/home/nick/.local/lib/python3.9/site-packages/vk_api/longpoll.py", line 557, in check
    response = self.session.get(
  File "/usr/lib/python3/dist-packages/requests/sessions.py", line 543, in get
    return self.request('GET', url, **kwargs)
  File "/usr/lib/python3/dist-packages/requests/sessions.py", line 530, in request
    resp = self.send(prep, **send_kwargs)
  File "/usr/lib/python3/dist-packages/requests/sessions.py", line 643, in send
    r = adapter.send(request, **kwargs)
  File "/usr/lib/python3/dist-packages/requests/adapters.py", line 439, in send
    resp = conn.urlopen(
  File "/usr/lib/python3/dist-packages/urllib3/connectionpool.py", line 670, in urlopen
    httplib_response = self._make_request(
  File "/usr/lib/python3/dist-packages/urllib3/connectionpool.py", line 426, in _make_request
    six.raise_from(e, None)
  File "<string>", line 3, in raise_from
  File "/usr/lib/python3/dist-packages/urllib3/connectionpool.py", line 421, in _make_request
    httplib_response = conn.getresponse()
  File "/usr/lib/python3.9/http/client.py", line 1347, in getresponse
    response.begin()
  File "/usr/lib/python3.9/http/client.py", line 307, in begin
    version, status, reason = self._read_status()
  File "/usr/lib/python3.9/http/client.py", line 268, in _read_status
    line = str(self.fp.readline(_MAXLINE + 1), "iso-8859-1")
  File "/usr/lib/python3.9/socket.py", line 704, in readinto
    return self._sock.recv_into(b)
  File "/usr/lib/python3.9/ssl.py", line 1241, in recv_into
    return self.read(nbytes, buffer)
  File "/usr/lib/python3.9/ssl.py", line 1099, in read
    return self._sslobj.read(len, buffer)
KeyboardInterrupt
"2021-12-05 00:57:16,239 - [INFO] -  logs.logger - (bot.py).start_polling(54) - Start polling"
"2021-12-05 00:57:18,257 - [INFO] -  logs.logger - (bot.py).run(44) - Домашка"
"2021-12-05 00:57:24,087 - [INFO] -  logs.logger - (bot.py).run(44) - сб"
"2021-12-05 00:57:32,179 - [INFO] -  logs.logger - (bot.py).start_polling(60) - Stop polling"
"2021-12-05 00:57:32,199 - [ERROR] -  asyncio - (base_events.py).default_exception_handler(1738) - Task exception was never retrieved
future: <Task finished name='Task-1' coro=<Bot.run() done, defined at /home/nick/PycharmProjects/vkbot/bot/bot.py:41> exception=KeyboardInterrupt()>"
Traceback (most recent call last):
  File "/home/nick/PycharmProjects/vkbot/bot/bot.py", line 58, in start_polling
    main_loop.run_forever()
  File "/usr/lib/python3.9/asyncio/base_events.py", line 596, in run_forever
    self._run_once()
  File "/usr/lib/python3.9/asyncio/base_events.py", line 1890, in _run_once
    handle._run()
  File "/usr/lib/python3.9/asyncio/events.py", line 80, in _run
    self._context.run(self._callback, *self._args)
  File "/home/nick/PycharmProjects/vkbot/bot/bot.py", line 42, in run
    for event in self._longpoll.listen():
  File "/home/nick/.local/lib/python3.9/site-packages/vk_api/longpoll.py", line 621, in listen
    for event in self.check():
  File "/home/nick/.local/lib/python3.9/site-packages/vk_api/longpoll.py", line 557, in check
    response = self.session.get(
  File "/usr/lib/python3/dist-packages/requests/sessions.py", line 543, in get
    return self.request('GET', url, **kwargs)
  File "/usr/lib/python3/dist-packages/requests/sessions.py", line 530, in request
    resp = self.send(prep, **send_kwargs)
  File "/usr/lib/python3/dist-packages/requests/sessions.py", line 643, in send
    r = adapter.send(request, **kwargs)
  File "/usr/lib/python3/dist-packages/requests/adapters.py", line 439, in send
    resp = conn.urlopen(
  File "/usr/lib/python3/dist-packages/urllib3/connectionpool.py", line 670, in urlopen
    httplib_response = self._make_request(
  File "/usr/lib/python3/dist-packages/urllib3/connectionpool.py", line 426, in _make_request
    six.raise_from(e, None)
  File "<string>", line 3, in raise_from
  File "/usr/lib/python3/dist-packages/urllib3/connectionpool.py", line 421, in _make_request
    httplib_response = conn.getresponse()
  File "/usr/lib/python3.9/http/client.py", line 1347, in getresponse
    response.begin()
  File "/usr/lib/python3.9/http/client.py", line 307, in begin
    version, status, reason = self._read_status()
  File "/usr/lib/python3.9/http/client.py", line 268, in _read_status
    line = str(self.fp.readline(_MAXLINE + 1), "iso-8859-1")
  File "/usr/lib/python3.9/socket.py", line 704, in readinto
    return self._sock.recv_into(b)
  File "/usr/lib/python3.9/ssl.py", line 1241, in recv_into
    return self.read(nbytes, buffer)
  File "/usr/lib/python3.9/ssl.py", line 1099, in read
    return self._sslobj.read(len, buffer)
KeyboardInterrupt
"2021-12-05 01:03:41,976 - [INFO] -  logs.logger - (bot.py).start_polling(54) - Start polling"
"2021-12-05 01:04:08,274 - [INFO] -  logs.logger - (bot.py).start_polling(54) - Start polling"
"2021-12-05 01:05:34,826 - [INFO] -  logs.logger - (bot.py).start_polling(54) - Start polling"
"2021-12-05 01:05:56,915 - [INFO] -  logs.logger - (bot.py).start_polling(54) - Start polling"
"2021-12-05 01:06:25,228 - [INFO] -  logs.logger - (bot.py).start_polling(54) - Start polling"
"2021-12-05 01:06:56,060 - [INFO] -  logs.logger - (bot.py).start_polling(54) - Start polling"
"2021-12-05 01:08:38,323 - [INFO] -  logs.logger - (bot.py).start_polling(54) - Start polling"
"2021-12-05 01:11:28,162 - [INFO] -  logs.logger - (bot.py).start_polling(54) - Start polling"
"2021-12-05 01:13:09,658 - [INFO] -  logs.logger - (bot.py).start_polling(54) - Start polling"
"2021-12-05 01:14:38,189 - [INFO] -  logs.logger - (bot.py).run(44) - Начать"
"2021-12-05 01:14:43,936 - [INFO] -  logs.logger - (bot.py).run(44) - АБс-123"
"2021-12-05 01:15:49,590 - [INFO] -  logs.logger - (bot.py).run(44) - Домашка"
"2021-12-05 01:15:51,637 - [INFO] -  logs.logger - (bot.py).run(44) - Все что есть"
"2021-12-05 01:16:17,228 - [INFO] -  logs.logger - (bot.py).run(44) - Добавить домашку"
"2021-12-05 01:16:21,155 - [INFO] -  logs.logger - (bot.py).run(44) - Иностранный язык"
"2021-12-05 01:16:33,188 - [INFO] -  logs.logger - (bot.py).run(44) - Задание по английскому"
"2021-12-05 01:16:35,702 - [INFO] -  logs.logger - (bot.py).run(44) - вт"
"2021-12-05 01:16:38,332 - [INFO] -  logs.logger - (bot.py).run(44) - Домашка"
"2021-12-05 01:16:39,975 - [INFO] -  logs.logger - (bot.py).run(44) - вт"
"2021-12-05 01:17:43,663 - [INFO] -  logs.logger - (bot.py).run(44) - Дедлайны"
